Workbook

Sheet Návod
A1: Hodnoticí model a hodnoticí arch – výběrové řízení SENTINEL
A2: Horizont Privátní banka, a.s. · Projekt SENTINEL – výměna KYC/AML řešení
A3: FIKTIVNÍ CVIČNÝ DOKUMENT – banka, osoby a dodavatelé jsou smyšlení.
B5: Postup hodnocení
B6: 1) K.O. brána (list 1_KO_brana): každé K.O. kritérium Pass/Fail. Jediný FAIL = nabídka nepostupuje do bodového hodnocení.
B7: 2) Byznys funkcionality 30 % (list 2_Byznys): odpovědi z Matice shody, body 5/3/1/0, váha MoSCoW, křížová kontrola s FS a ověření v demu.
B8: 3) Architektura a bezpečnost 20 % (list 3_Arch_Sec): každý hlasující člen komise boduje kapitoly FS na škále 0–10.
B9: 4) Delivery a zkušenosti 10 % (list 4_Delivery): reference z finančního sektoru, seniorita týmu, návrh SLA, projektový plán – škála 0–10.
B10: 5) Cena 40 % (list 5_Cena): (nejnižší TCO / hodnocené TCO) × 40, jen pro nabídky, které prošly K.O. bránou.
B11: 6) Výsledek (list Vysledek) a hodnoticí arch k podpisu (list Hodnotici_arch).
B12: Pravidla auditní stopy
B13: • Váhy a stupnice schválil SteerCo 23. 9. 2026, tj. PŘED vyhlášením výběrového řízení. Po otevření nabídek se nemění.
B14: • Každá známka horší než průměr daného kritéria musí mít jednovětné zdůvodnění – buňka jinak zčervená.
B15: • Členové komise podepisují prohlášení o neexistenci střetu zájmů před otevřením nabídek.
B16: • Data v tomto souboru jsou FIKTIVNÍ ukázkou výpočtu (3 smyšlení dodavatelé).
... B22: Vypočteno vzorcem – needitovat

Sheet Parametry
A1: Parametry hodnocení (schváleno SteerCo 23. 9. 2026)
A2: Horizont Privátní banka, a.s. · Projekt SENTINEL – výměna KYC/AML řešení
A3: FIKTIVNÍ CVIČNÝ DOKUMENT – banka, osoby a dodavatelé jsou smyšlení.
A5: Kategorie | B5: Váha | C5: Zdroj dat | D5: Metoda
A6: Cena (TCO na 5 let) | B6: 0.4 | C6: Příloha 3 – cenová šablona | D6: (nejnižší TCO / hodnocené TCO) × 40
A7: Byznys funkcionality | B7: 0.3 | C7: Příloha 1 – Matice shody | D7: Σ(uznané body × váha MoSCoW) / Σ(5 × váha MoSCoW) × 30
A8: Architektura & bezpečnost | B8: 0.2 | C8: Příloha 2 – Feasibility Study | D8: průměr známek komise 0–10 / 10 × 20
A9: Delivery a zkušenosti | B9: 0.1 | C9: Reference, CV, návrh SLA, plán | D9: průměr známek komise 0–10 / 10 × 10
A10: Součet vah | B10: =SUM(B6:B9)
A12: Stupnice FS a Delivery (0–10)
A13: 8–10: detailní návrh přesně na rozhraní a systémy Banky
A14: 4–7: standardizovaný popis, chybí detail na specifické systémy Banky (core, CRM)
A15: 0–3: obecné marketingové fráze bez technické hloubky

Sheet 1_KO_brana
A1: 1 – K.O. brána (Pass/Fail)
A2: Horizont Privátní banka, a.s. · Projekt SENTINEL – výměna KYC/AML řešení
A3: FIKTIVNÍ CVIČNÝ DOKUMENT – banka, osoby a dodavatelé jsou smyšlení.
A5: ID | B5: K.O. kritérium | C5: Doklad | D5: Dodavatel A | E5: Dodavatel B | F5: Dodavatel C | G5: Poznámka komise
A6: FORM-01 | B6: Nabídka podána včas a v požadované struktuře (Matice, FS, TCO, přílohy) | C6: Protokol o otevření nabídek | D6: PASS | E6: PASS | F6: PASS
A7: FORM-02 | B7: Podepsaná NDA a čestné prohlášení (bezúhonnost, sankce, střet zájmů) | C7: Čestné prohlášení dle Přílohy 7 | D7: PASS | E7: PASS | F7: PASS
A8: FORM-03 | B8: Kompletní cenová šablona – stav KOMPLETNÍ a všechna potvrzení „Ano“ | C8: Příloha 3, list Souhrn | D8: PASS | E8: PASS | F8: PASS
A9: SCR-001 | B9: Screening klientů, zástupců, skutečných majitelů a protistran proti sankčním seznamům EU (konsolidovaný seznam), OSN, národnímu sankčnímu seznamu ČR a volitelně OFAC a UK HMT. | C9: Matice shody, FS kap. 6.2 | D9: PASS | E9: PASS | F9: PASS
A10: INT-001 | B10: Obousměrná integrace s CRM přes REST API: požadavek na onboarding, stav KYC, rizikový profil, termín revize a rozhodnutí; změny z AML se do CRM posílají událostmi. | C10: Matice shody, FS kap. 5.1 | D10: PASS | E10: PASS | F10: PASS
A11: NFR-006 | B11: Provoz on-premise v datových centrech Banky nebo v privátním cloudu; data a zálohy výhradně v EU/EHP. | C11: Matice shody, FS kap. 3.1 | D11: PASS | E11: PASS | F11: FAIL | G11: Dodavatel C: Zálohy v regionu mimo EU/EHP (USA); 2. linie podpory z Indie.
A12: SEC-001 | B12: Systém podporuje SAML 2.0 / OIDC pro jednotné přihlášení (SSO) přes bankovní IAM. | C12: Matice shody, FS kap. 4.2 | D12: PASS | E12: PASS | F12: PASS
A13: SEC-010 | B13: Dodavatel je držitelem platné certifikace ISO/IEC 27001 nebo zprávy SOC 2 Type II pro organizaci zajišťující vývoj a podporu. | C13: Matice shody, FS kap. 4.1 | D13: PASS | E13: PASS | F13: PASS
A14: REG-001 | B14: Dodavatel akceptuje smluvní ujednání dle čl. 30 DORA a poskytne údaje pro registr informací Banky. | C14: Matice shody, FS kap. 9.1 | D14: PASS | E14: PASS | F14: PASS
A15: LEG-001 | B15: Osobní údaje jsou zpracovávány výhradně v EU/EHP; jakýkoli přístup z třetích zemí (včetně vzdálené podpory) jen s předchozím písemným souhlasem Banky. | C15: Matice shody, FS kap. 9.1 | D15: PASS | E15: PASS | F15: FAIL | G15: Dodavatel C: Neakceptuje omezení vzdáleného přístupu z třetích zemí.
A16: LEG-002 | B16: Uzavření smlouvy o zpracování osobních údajů dle čl. 28 GDPR na vzoru Banky. | C16: Matice shody, FS kap. 9.1 | D16: PASS | E16: PASS | F16: PASS
B17: Výsledek K.O. brány | D17: =IF(COUNTIF(D6:D16,"FAIL")>0,"VYŘAZEN",IF(COUNTIF(D6:D16,"PASS")=11,"POSTUPUJE","NEÚPLNÉ")) | E17: =IF(COUNTIF(E6:E16,"FAIL")>0,"VYŘAZEN",IF(COUNTIF(E6:E16,"PASS")=11,"POSTUPUJE","NEÚPLNÉ")) | F17: =IF(COUNTIF(F6:F16,"FAIL")>0,"VYŘAZEN",IF(COUNTIF(F6:F16,"PASS")=11,"POSTUPUJE","NEÚPLNÉ"))

Sheet 2_Byznys
A1: 2 – Byznys funkcionality (30 %) – odpovědi z Matice shody
A2: Horizont Privátní banka, a.s. · Projekt SENTINEL – výměna KYC/AML řešení
A3: FIKTIVNÍ CVIČNÝ DOKUMENT – banka, osoby a dodavatelé jsou smyšlení.
A5: ID | B5: Požadavek | C5: MoSCoW | D5: Váha | E5: Dodavatel A Odpověď | F5: Odkaz FS | G5: Ověřeno (FS/demo) | H5: Uznané body | I5: Dodavatel B Odpověď | J5: Odkaz FS | K5: Ověřeno (FS/demo) | L5: Uznané body | M5: Dodavatel C Odpověď | N5: Odkaz FS | O5: Ověřeno (FS/demo) | P5: Uznané body | Q5: Zdůvodnění komise (povinné při snížení bodů)
A6: KYC-001 | B6: Systém při onboardingu automaticky vypočte rizikový profil klienta (nízké / střední / vysoké / nepřijatelné riziko) z konfigurovatelných rizikových faktorů: typ klienta, země (bydliště, občanství, sídlo, zdroj majetku), produkt, distribuční kanál, objem aktiv a struktura vlastnictví. | C6: Must | D6: =IF(C6="Must",3,IF(C6="Should",2,IF(C6="Could",1,0))) | E6: Konfigurace | F6: 6.1 | G6: Ano | H6: =IF(E6="","",IF(OR(AND(OR(E6="OOTB",E6="Konfigurace",E6="Custom vývoj"),F6=""),G6="Ne"),0,IF(E6="OOTB",5,IF(E6="Konfigurace",3,IF(E6="Custom vývoj",1,0))))) | I6: Konfigurace | J6: 6.1 | K6: Ano | L6: =IF(I6="","",IF(OR(AND(OR(I6="OOTB",I6="Konfigurace",I6="Custom vývoj"),J6=""),K6="Ne"),0,IF(I6="OOTB",5,IF(I6="Konfigurace",3,IF(I6="Custom vývoj",1,0))))) | M6: OOTB | N6: 6.1 | O6: Ano | P6: =IF(M6="","",IF(OR(AND(OR(M6="OOTB",M6="Konfigurace",M6="Custom vývoj"),N6=""),O6="Ne"),0,IF(M6="OOTB",5,IF(M6="Konfigurace",3,IF(M6="Custom vývoj",1,0)))))
A7: KYC-002 | B7: U každého výpočtu rizikového profilu je uložen vstup, použitá verze rizikového modelu, dílčí skóre faktorů a výsledné zdůvodnění; výpočet lze zpětně zrekonstruovat. | C7: Must | D7: =IF(C7="Must",3,IF(C7="Should",2,IF(C7="Could",1,0))) | E7: Konfigurace | F7: 9.2 | G7: Ano | H7: =IF(E7="","",IF(OR(AND(OR(E7="OOTB",E7="Konfigurace",E7="Custom vývoj"),F7=""),G7="Ne"),0,IF(E7="OOTB",5,IF(E7="Konfigurace",3,IF(E7="Custom vývoj",1,0))))) | I7: 3rd party | L7: =IF(I7="","",IF(OR(AND(OR(I7="OOTB",I7="Konfigurace",I7="Custom vývoj"),J7=""),K7="Ne"),0,IF(I7="OOTB",5,IF(I7="Konfigurace",3,IF(I7="Custom vývoj",1,0))))) | M7: Nesplněno | P7: =IF(M7="","",IF(OR(AND(OR(M7="OOTB",M7="Konfigurace",M7="Custom vývoj"),N7=""),O7="Ne"),0,IF(M7="OOTB",5,IF(M7="Konfigurace",3,IF(M7="Custom vývoj",1,0)))))
A8: KYC-003 | B8: Systém vynutí zesílenou kontrolu (EDD) pro vysoce rizikové klienty, PEP a klienty s vazbou na vysoce rizikové třetí země dle seznamu Evropské komise; workflow obsahuje povinné kroky, schválení vedoucím a uložení podkladů. | C8: Must | D8: =IF(C8="Must",3,IF(C8="Should",2,IF(C8="Could",1,0))) | E8: OOTB | F8: 6.1 | G8: Ano | H8: =IF(E8="","",IF(OR(AND(OR(E8="OOTB",E8="Konfigurace",E8="Custom vývoj"),F8=""),G8="Ne"),0,IF(E8="OOTB",5,IF(E8="Konfigurace",3,IF(E8="Custom vývoj",1,0))))) | I8: Konfigurace | J8: 6.1 | K8: Ano | L8: =IF(I8="","",IF(OR(AND(OR(I8="OOTB",I8="Konfigurace",I8="Custom vývoj"),J8=""),K8="Ne"),0,IF(I8="OOTB",5,IF(I8="Konfigurace",3,IF(I8="Custom vývoj",1,0))))) | M8: OOTB | N8: 6.1 | O8: Ano | P8: =IF(M8="","",IF(OR(AND(OR(M8="OOTB",M8="Konfigurace",M8="Custom vývoj"),N8=""),O8="Ne"),0,IF(M8="OOTB",5,IF(M8="Konfigurace",3,IF(M8="Custom vývoj",1,0)))))
A9: KYC-004 | B9: Evidence a ověření skutečného majitele (UBO) včetně vícevrstvých vlastnických struktur (holdingy, svěřenské fondy, trusty, nadace) s grafickou vizualizací struktury a výpočtem nepřímého podílu. | C9: Must | D9: =IF(C9="Must",3,IF(C9="Should",2,IF(C9="Could",1,0))) | E9: OOTB | F9: 6.1 | G9: Ano | H9: =IF(E9="","",IF(OR(AND(OR(E9="OOTB",E9="Konfigurace",E9="Custom vývoj"),F9=""),G9="Ne"),0,IF(E9="OOTB",5,IF(E9="Konfigurace",3,IF(E9="Custom vývoj",1,0))))) | I9: OOTB | J9: 6.1 | K9: Ano | L9: =IF(I9="","",IF(OR(AND(OR(I9="OOTB",I9="Konfigurace",I9="Custom vývoj"),J9=""),K9="Ne"),0,IF(I9="OOTB",5,IF(I9="Konfigurace",3,IF(I9="Custom vývoj",1,0))))) | M9: Konfigurace | N9: 6.1 | O9: Ano | P9: =IF(M9="","",IF(OR(AND(OR(M9="OOTB",M9="Konfigurace",M9="Custom vývoj"),N9=""),O9="Ne"),0,IF(M9="OOTB",5,IF(M9="Konfigurace",3,IF(M9="Custom vývoj",1,0)))))
A10: KYC-005 | B10: Porovnání evidovaných skutečných majitelů s Evidencí skutečných majitelů (ESM) a podpora procesu hlášení nesrovnalosti. | C10: Should | D10: =IF(C10="Must",3,IF(C10="Should",2,IF(C10="Could",1,0))) | E10: Konfigurace | F10: 5.6 | G10: Ano | H10: =IF(E10="","",IF(OR(AND(OR(E10="OOTB",E10="Konfigurace",E10="Custom vývoj"),F10=""),G10="Ne"),0,IF(E10="OOTB",5,IF(E10="Konfigurace",3,IF(E10="Custom vývoj",1,0))))) | I10: OOTB | J10: 5.6 | K10: Ano | L10: =IF(I10="","",IF(OR(AND(OR(I10="OOTB",I10="Konfigurace",I10="Custom vývoj"),J10=""),K10="Ne"),0,IF(I10="OOTB",5,IF(I10="Konfigurace",3,IF(I10="Custom vývoj",1,0))))) | M10: OOTB | N10: 5.6 | O10: Ano | P10: =IF(M10="","",IF(OR(AND(OR(M10="OOTB",M10="Konfigurace",M10="Custom vývoj"),N10=""),O10="Ne"),0,IF(M10="OOTB",5,IF(M10="Konfigurace",3,IF(M10="Custom vývoj",1,0)))))
A11: KYC-006 | B11: Načtení údajů o právnické osobě z veřejných rejstříků (ARES, obchodní rejstřík) při onboardingu i při revizi. | C11: Should | D11: =IF(C11="Must",3,IF(C11="Should",2,IF(C11="Could",1,0))) | E11: OOTB | F11: 5.6 | G11: Ano | H11: =IF(E11="","",IF(OR(AND(OR(E11="OOTB",E11="Konfigurace",E11="Custom vývoj"),F11=""),G11="Ne"),0,IF(E11="OOTB",5,IF(E11="Konfigurace",3,IF(E11="Custom vývoj",1,0))))) | I11: Konfigurace | J11: 5.6 | K11: Ano | L11: =IF(I11="","",IF(OR(AND(OR(I11="OOTB",I11="Konfigurace",I11="Custom vývoj"),J11=""),K11="Ne"),0,IF(I11="OOTB",5,IF(I11="Konfigurace",3,IF(I11="Custom vývoj",1,0))))) | M11: Konfigurace | N11: 5.6 | O11: Ano | P11: =IF(M11="","",IF(OR(AND(OR(M11="OOTB",M11="Konfigurace",M11="Custom vývoj"),N11=""),O11="Ne"),0,IF(M11="OOTB",5,IF(M11="Konfigurace",3,IF(M11="Custom vývoj",1,0)))))
A12: KYC-007 | B12: Příjem výsledku vzdálené identifikace klienta prostřednictvím bankovní identity (BankID) a jeho uložení jako důkazu o identifikaci. | C12: Could | D12: =IF(C12="Must",3,IF(C12="Should",2,IF(C12="Could",1,0))) | E12: OOTB | F12: 5.6 | G12: Ano | H12: =IF(E12="","",IF(OR(AND(OR(E12="OOTB",E12="Konfigurace",E12="Custom vývoj"),F12=""),G12="Ne"),0,IF(E12="OOTB",5,IF(E12="Konfigurace",3,IF(E12="Custom vývoj",1,0))))) | I12: 3rd party | L12: =IF(I12="","",IF(OR(AND(OR(I12="OOTB",I12="Konfigurace",I12="Custom vývoj"),J12=""),K12="Ne"),0,IF(I12="OOTB",5,IF(I12="Konfigurace",3,IF(I12="Custom vývoj",1,0))))) | M12: OOTB | N12: 5.6 | O12: Ano | P12: =IF(M12="","",IF(OR(AND(OR(M12="OOTB",M12="Konfigurace",M12="Custom vývoj"),N12=""),O12="Ne"),0,IF(M12="OOTB",5,IF(M12="Konfigurace",3,IF(M12="Custom vývoj",1,0)))))
A13: KYC-008 | B13: Periodická revize klienta plánovaná podle rizikovosti (vysoké 1 rok, střední 3 roky, nízké 5 let – konfigurovatelné) s automatickým založením úkolu pro obchodníka v CRM. | C13: Must | D13: =IF(C13="Must",3,IF(C13="Should",2,IF(C13="Could",1,0))) | E13: Konfigurace | F13: 6.1 | G13: Ano | H13: =IF(E13="","",IF(OR(AND(OR(E13="OOTB",E13="Konfigurace",E13="Custom vývoj"),F13=""),G13="Ne"),0,IF(E13="OOTB",5,IF(E13="Konfigurace",3,IF(E13="Custom vývoj",1,0))))) | I13: Konfigurace | J13: 6.1 | K13: Ano | L13: =IF(I13="","",IF(OR(AND(OR(I13="OOTB",I13="Konfigurace",I13="Custom vývoj"),J13=""),K13="Ne"),0,IF(I13="OOTB",5,IF(I13="Konfigurace",3,IF(I13="Custom vývoj",1,0))))) | M13: OOTB | N13: 6.1 | O13: Ano | P13: =IF(M13="","",IF(OR(AND(OR(M13="OOTB",M13="Konfigurace",M13="Custom vývoj"),N13=""),O13="Ne"),0,IF(M13="OOTB",5,IF(M13="Konfigurace",3,IF(M13="Custom vývoj",1,0)))))
A14: KYC-009 | B14: Událostmi řízená revize: změna rizikově relevantního údaje v CRM (adresa, státní občanství, UBO, předmět podnikání) vyvolá přepočet rizikového profilu a re-screening do 15 minut. | C14: Must | D14: =IF(C14="Must",3,IF(C14="Should",2,IF(C14="Could",1,0))) | E14: OOTB | F14: 5.1 | G14: Ano | H14: =IF(E14="","",IF(OR(AND(OR(E14="OOTB",E14="Konfigurace",E14="Custom vývoj"),F14=""),G14="Ne"),0,IF(E14="OOTB",5,IF(E14="Konfigurace",3,IF(E14="Custom vývoj",1,0))))) | I14: Custom vývoj | J14: 6.6 | K14: Ano | L14: =IF(I14="","",IF(OR(AND(OR(I14="OOTB",I14="Konfigurace",I14="Custom vývoj"),J14=""),K14="Ne"),0,IF(I14="OOTB",5,IF(I14="Konfigurace",3,IF(I14="Custom vývoj",1,0))))) | M14: OOTB | N14: 5.1 | O14: Ano | P14: =IF(M14="","",IF(OR(AND(OR(M14="OOTB",M14="Konfigurace",M14="Custom vývoj"),N14=""),O14="Ne"),0,IF(M14="OOTB",5,IF(M14="Konfigurace",3,IF(M14="Custom vývoj",1,0)))))
A15: KYC-010 | B15: Strukturovaný dotazník ke zdroji majetku (SoW) a zdroji finančních prostředků (SoF) s možností přiložit doklady, s verzováním odpovědí a vyhodnocením věrohodnosti. | C15: Must | D15: =IF(C15="Must",3,IF(C15="Should",2,IF(C15="Could",1,0))) | E15: Custom vývoj | F15: 6.6 | G15: Ano | H15: =IF(E15="","",IF(OR(AND(OR(E15="OOTB",E15="Konfigurace",E15="Custom vývoj"),F15=""),G15="Ne"),0,IF(E15="OOTB",5,IF(E15="Konfigurace",3,IF(E15="Custom vývoj",1,0))))) | I15: Custom vývoj | J15: 6.6 | K15: Ano | L15: =IF(I15="","",IF(OR(AND(OR(I15="OOTB",I15="Konfigurace",I15="Custom vývoj"),J15=""),K15="Ne"),0,IF(I15="OOTB",5,IF(I15="Konfigurace",3,IF(I15="Custom vývoj",1,0))))) | M15: Nesplněno | P15: =IF(M15="","",IF(OR(AND(OR(M15="OOTB",M15="Konfigurace",M15="Custom vývoj"),N15=""),O15="Ne"),0,IF(M15="OOTB",5,IF(M15="Konfigurace",3,IF(M15="Custom vývoj",1,0)))))
A16: KYC-011 | B16: Obchodník vidí stav KYC, rizikovost, termín revize a otevřené případy klienta přímo v CRM bez přepnutí do jiné aplikace (embedded komponenta nebo API). | C16: Must | D16: =IF(C16="Must",3,IF(C16="Should",2,IF(C16="Could",1,0))) | E16: Konfigurace | F16: 5.1 | G16: Ano | H16: =IF(E16="","",IF(OR(AND(OR(E16="OOTB",E16="Konfigurace",E16="Custom vývoj"),F16=""),G16="Ne"),0,IF(E16="OOTB",5,IF(E16="Konfigurace",3,IF(E16="Custom vývoj",1,0))))) | I16: Custom vývoj | J16: 6.6 | K16: Ano | L16: =IF(I16="","",IF(OR(AND(OR(I16="OOTB",I16="Konfigurace",I16="Custom vývoj"),J16=""),K16="Ne"),0,IF(I16="OOTB",5,IF(I16="Konfigurace",3,IF(I16="Custom vývoj",1,0))))) | M16: Konfigurace | N16: 5.1 | O16: Ano | P16: =IF(M16="","",IF(OR(AND(OR(M16="OOTB",M16="Konfigurace",M16="Custom vývoj"),N16=""),O16="Ne"),0,IF(M16="OOTB",5,IF(M16="Konfigurace",3,IF(M16="Custom vývoj",1,0)))))
A17: KYC-012 | B17: Formuláře KYC se předvyplní z dat CRM; obchodník nezadává žádný údaj dvakrát. | C17: Should | D17: =IF(C17="Must",3,IF(C17="Should",2,IF(C17="Could",1,0))) | E17: OOTB | F17: 5.1 | G17: Ano | H17: =IF(E17="","",IF(OR(AND(OR(E17="OOTB",E17="Konfigurace",E17="Custom vývoj"),F17=""),G17="Ne"),0,IF(E17="OOTB",5,IF(E17="Konfigurace",3,IF(E17="Custom vývoj",1,0))))) | I17: Custom vývoj | J17: 6.6 | K17: Ano | L17: =IF(I17="","",IF(OR(AND(OR(I17="OOTB",I17="Konfigurace",I17="Custom vývoj"),J17=""),K17="Ne"),0,IF(I17="OOTB",5,IF(I17="Konfigurace",3,IF(I17="Custom vývoj",1,0))))) | M17: Konfigurace | N17: 5.1 | O17: Ano | P17: =IF(M17="","",IF(OR(AND(OR(M17="OOTB",M17="Konfigurace",M17="Custom vývoj"),N17=""),O17="Ne"),0,IF(M17="OOTB",5,IF(M17="Konfigurace",3,IF(M17="Custom vývoj",1,0)))))
A18: KYC-013 | B18: Klientské formuláře a dotazníky v češtině, angličtině a němčině; další jazyk lze doplnit konfigurací. | C18: Should | D18: =IF(C18="Must",3,IF(C18="Should",2,IF(C18="Could",1,0))) | E18: OOTB | F18: 6.1 | G18: Ano | H18: =IF(E18="","",IF(OR(AND(OR(E18="OOTB",E18="Konfigurace",E18="Custom vývoj"),F18=""),G18="Ne"),0,IF(E18="OOTB",5,IF(E18="Konfigurace",3,IF(E18="Custom vývoj",1,0))))) | I18: OOTB | J18: 6.1 | K18: Ano | L18: =IF(I18="","",IF(OR(AND(OR(I18="OOTB",I18="Konfigurace",I18="Custom vývoj"),J18=""),K18="Ne"),0,IF(I18="OOTB",5,IF(I18="Konfigurace",3,IF(I18="Custom vývoj",1,0))))) | M18: Konfigurace | N18: 6.1 | O18: Ano | P18: =IF(M18="","",IF(OR(AND(OR(M18="OOTB",M18="Konfigurace",M18="Custom vývoj"),N18=""),O18="Ne"),0,IF(M18="OOTB",5,IF(M18="Konfigurace",3,IF(M18="Custom vývoj",1,0)))))
A19: KYC-014 | B19: Eskalace nesplněné revize: po termínu upozornění obchodníkovi, po 30 dnech jeho nadřízenému a Compliance, po 90 dnech návrh na omezení služeb. | C19: Should | D19: =IF(C19="Must",3,IF(C19="Should",2,IF(C19="Could",1,0))) | E19: OOTB | F19: 6.1 | G19: Ano | H19: =IF(E19="","",IF(OR(AND(OR(E19="OOTB",E19="Konfigurace",E19="Custom vývoj"),F19=""),G19="Ne"),0,IF(E19="OOTB",5,IF(E19="Konfigurace",3,IF(E19="Custom vývoj",1,0))))) | I19: Konfigurace | J19: 6.1 | K19: Ano | L19: =IF(I19="","",IF(OR(AND(OR(I19="OOTB",I19="Konfigurace",I19="Custom vývoj"),J19=""),K19="Ne"),0,IF(I19="OOTB",5,IF(I19="Konfigurace",3,IF(I19="Custom vývoj",1,0))))) | M19: Konfigurace | N19: 6.1 | O19: Ano | P19: =IF(M19="","",IF(OR(AND(OR(M19="OOTB",M19="Konfigurace",M19="Custom vývoj"),N19=""),O19="Ne"),0,IF(M19="OOTB",5,IF(M19="Konfigurace",3,IF(M19="Custom vývoj",1,0)))))
A20: KYC-015 | B20: Podpora zjednodušené kontroly klienta (SDD) pro definované kategorie klientů s nízkým rizikem. | C20: Could | D20: =IF(C20="Must",3,IF(C20="Should",2,IF(C20="Could",1,0))) | E20: OOTB | F20: 6.1 | G20: Ano | H20: =IF(E20="","",IF(OR(AND(OR(E20="OOTB",E20="Konfigurace",E20="Custom vývoj"),F20=""),G20="Ne"),0,IF(E20="OOTB",5,IF(E20="Konfigurace",3,IF(E20="Custom vývoj",1,0))))) | I20: Konfigurace | J20: 6.1 | K20: Ano | L20: =IF(I20="","",IF(OR(AND(OR(I20="OOTB",I20="Konfigurace",I20="Custom vývoj"),J20=""),K20="Ne"),0,IF(I20="OOTB",5,IF(I20="Konfigurace",3,IF(I20="Custom vývoj",1,0))))) | M20: Konfigurace | N20: 6.1 | O20: Ano | P20: =IF(M20="","",IF(OR(AND(OR(M20="OOTB",M20="Konfigurace",M20="Custom vývoj"),N20=""),O20="Ne"),0,IF(M20="OOTB",5,IF(M20="Konfigurace",3,IF(M20="Custom vývoj",1,0)))))
A21: SCR-002 | B21: Screening politicky exponovaných osob (PEP) včetně rodinných příslušníků a osob blízkých (RCA), s rozlišením domácích a zahraničních PEP. | C21: Must | D21: =IF(C21="Must",3,IF(C21="Should",2,IF(C21="Could",1,0))) | E21: Konfigurace | F21: 6.2 | G21: Ano | H21: =IF(E21="","",IF(OR(AND(OR(E21="OOTB",E21="Konfigurace",E21="Custom vývoj"),F21=""),G21="Ne"),0,IF(E21="OOTB",5,IF(E21="Konfigurace",3,IF(E21="Custom vývoj",1,0))))) | I21: OOTB | J21: 6.2 | K21: Ano | L21: =IF(I21="","",IF(OR(AND(OR(I21="OOTB",I21="Konfigurace",I21="Custom vývoj"),J21=""),K21="Ne"),0,IF(I21="OOTB",5,IF(I21="Konfigurace",3,IF(I21="Custom vývoj",1,0))))) | M21: Konfigurace | N21: 6.2 | O21: Ano | P21: =IF(M21="","",IF(OR(AND(OR(M21="OOTB",M21="Konfigurace",M21="Custom vývoj"),N21=""),O21="Ne"),0,IF(M21="OOTB",5,IF(M21="Konfigurace",3,IF(M21="Custom vývoj",1,0)))))
A22: SCR-003 | B22: Screening negativních zpráv (adverse media) s konfigurovatelnými kategoriemi (finanční kriminalita, korupce, organizovaný zločin, daňové delikty). | C22: Should | D22: =IF(C22="Must",3,IF(C22="Should",2,IF(C22="Could",1,0))) | E22: OOTB | F22: 6.2 | G22: Ano | H22: =IF(E22="","",IF(OR(AND(OR(E22="OOTB",E22="Konfigurace",E22="Custom vývoj"),F22=""),G22="Ne"),0,IF(E22="OOTB",5,IF(E22="Konfigurace",3,IF(E22="Custom vývoj",1,0))))) | I22: Konfigurace | J22: 6.2 | K22: Ano | L22: =IF(I22="","",IF(OR(AND(OR(I22="OOTB",I22="Konfigurace",I22="Custom vývoj"),J22=""),K22="Ne"),0,IF(I22="OOTB",5,IF(I22="Konfigurace",3,IF(I22="Custom vývoj",1,0))))) | M22: Nesplněno | P22: =IF(M22="","",IF(OR(AND(OR(M22="OOTB",M22="Konfigurace",M22="Custom vývoj"),N22=""),O22="Ne"),0,IF(M22="OOTB",5,IF(M22="Konfigurace",3,IF(M22="Custom vývoj",1,0)))))
A23: SCR-004 | B23: Denní re-screening celé klientské báze a mimořádný re-screening do 1 hodiny od zveřejnění změny sankčního seznamu EU. | C23: Must | D23: =IF(C23="Must",3,IF(C23="Should",2,IF(C23="Could",1,0))) | E23: OOTB | F23: 6.2 | G23: Ano | H23: =IF(E23="","",IF(OR(AND(OR(E23="OOTB",E23="Konfigurace",E23="Custom vývoj"),F23=""),G23="Ne"),0,IF(E23="OOTB",5,IF(E23="Konfigurace",3,IF(E23="Custom vývoj",1,0))))) | I23: 3rd party | L23: =IF(I23="","",IF(OR(AND(OR(I23="OOTB",I23="Konfigurace",I23="Custom vývoj"),J23=""),K23="Ne"),0,IF(I23="OOTB",5,IF(I23="Konfigurace",3,IF(I23="Custom vývoj",1,0))))) | M23: OOTB | N23: 6.2 | O23: Ano | P23: =IF(M23="","",IF(OR(AND(OR(M23="OOTB",M23="Konfigurace",M23="Custom vývoj"),N23=""),O23="Ne"),0,IF(M23="OOTB",5,IF(M23="Konfigurace",3,IF(M23="Custom vývoj",1,0)))))
A24: SCR-005 | B24: Fuzzy matching jmen s podporou transliterace (cyrilice, arabské písmo, čínské znaky), zaměnitelných pořadí jmen a diakritiky; prahy shody nastavitelné bez vývoje. | C24: Must | D24: =IF(C24="Must",3,IF(C24="Should",2,IF(C24="Could",1,0))) | E24: OOTB | F24: 6.2 | G24: Ano | H24: =IF(E24="","",IF(OR(AND(OR(E24="OOTB",E24="Konfigurace",E24="Custom vývoj"),F24=""),G24="Ne"),0,IF(E24="OOTB",5,IF(E24="Konfigurace",3,IF(E24="Custom vývoj",1,0))))) | I24: OOTB | J24: 6.2 | K24: Ne | L24: =IF(I24="","",IF(OR(AND(OR(I24="OOTB",I24="Konfigurace",I24="Custom vývoj"),J24=""),K24="Ne"),0,IF(I24="OOTB",5,IF(I24="Konfigurace",3,IF(I24="Custom vývoj",1,0))))) | M24: OOTB | N24: 6.2 | O24: Ano | P24: =IF(M24="","",IF(OR(AND(OR(M24="OOTB",M24="Konfigurace",M24="Custom vývoj"),N24=""),O24="Ne"),0,IF(M24="OOTB",5,IF(M24="Konfigurace",3,IF(M24="Custom vývoj",1,0))))) | Q24: Dodavatel B: V demu transliterace cyrilice nefungovala, shoda nalezena jen pro latinku.
A25: SCR-006 | B25: Seznam vyloučených shod (good-guy / whitelist) s povinným schválením čtyřma očima, zdůvodněním a datem expirace. | C25: Must | D25: =IF(C25="Must",3,IF(C25="Should",2,IF(C25="Could",1,0))) | E25: Konfigurace | F25: 6.2 | G25: Ano | H25: =IF(E25="","",IF(OR(AND(OR(E25="OOTB",E25="Konfigurace",E25="Custom vývoj"),F25=""),G25="Ne"),0,IF(E25="OOTB",5,IF(E25="Konfigurace",3,IF(E25="Custom vývoj",1,0))))) | I25: Konfigurace | J25: 6.2 | K25: Ano | L25: =IF(I25="","",IF(OR(AND(OR(I25="OOTB",I25="Konfigurace",I25="Custom vývoj"),J25=""),K25="Ne"),0,IF(I25="OOTB",5,IF(I25="Konfigurace",3,IF(I25="Custom vývoj",1,0))))) | M25: OOTB | N25: 6.2 | O25: Ano | P25: =IF(M25="","",IF(OR(AND(OR(M25="OOTB",M25="Konfigurace",M25="Custom vývoj"),N25=""),O25="Ne"),0,IF(M25="OOTB",5,IF(M25="Konfigurace",3,IF(M25="Custom vývoj",1,0)))))
A26: SCR-007 | B26: Online screening odchozích a příchozích zahraničních plateb (SWIFT, SEPA) vůči sankčním seznamům před jejich zpracováním, s možností pozastavit platbu. | C26: Must | D26: =IF(C26="Must",3,IF(C26="Should",2,IF(C26="Could",1,0))) | E26: OOTB | F26: 5.4 | G26: Ano | H26: =IF(E26="","",IF(OR(AND(OR(E26="OOTB",E26="Konfigurace",E26="Custom vývoj"),F26=""),G26="Ne"),0,IF(E26="OOTB",5,IF(E26="Konfigurace",3,IF(E26="Custom vývoj",1,0))))) | I26: OOTB | J26: 5.4 | K26: Ano | L26: =IF(I26="","",IF(OR(AND(OR(I26="OOTB",I26="Konfigurace",I26="Custom vývoj"),J26=""),K26="Ne"),0,IF(I26="OOTB",5,IF(I26="Konfigurace",3,IF(I26="Custom vývoj",1,0))))) | M26: OOTB | N26: 5.4 | O26: Ano | P26: =IF(M26="","",IF(OR(AND(OR(M26="OOTB",M26="Konfigurace",M26="Custom vývoj"),N26=""),O26="Ne"),0,IF(M26="OOTB",5,IF(M26="Konfigurace",3,IF(M26="Custom vývoj",1,0)))))
A27: SCR-008 | B27: Měření míry falešně pozitivních shod a možnost otestovat změnu nastavení screeningu nad historickými daty (what-if) před nasazením. | C27: Should | D27: =IF(C27="Must",3,IF(C27="Should",2,IF(C27="Could",1,0))) | E27: Konfigurace | F27: 6.2 | G27: Ano | H27: =IF(E27="","",IF(OR(AND(OR(E27="OOTB",E27="Konfigurace",E27="Custom vývoj"),F27=""),G27="Ne"),0,IF(E27="OOTB",5,IF(E27="Konfigurace",3,IF(E27="Custom vývoj",1,0))))) | I27: OOTB | J27: 6.2 | K27: Ano | L27: =IF(I27="","",IF(OR(AND(OR(I27="OOTB",I27="Konfigurace",I27="Custom vývoj"),J27=""),K27="Ne"),0,IF(I27="OOTB",5,IF(I27="Konfigurace",3,IF(I27="Custom vývoj",1,0))))) | M27: OOTB | N27: 6.2 | O27: Ano | P27: =IF(M27="","",IF(OR(AND(OR(M27="OOTB",M27="Konfigurace",M27="Custom vývoj"),N27=""),O27="Ne"),0,IF(M27="OOTB",5,IF(M27="Konfigurace",3,IF(M27="Custom vývoj",1,0)))))
A28: SCR-009 | B28: Řešení podporuje alespoň dva komerční zdroje dat PEP/adverse media; náklady na datové zdroje jsou uvedeny v cenové nabídce. | C28: Should | D28: =IF(C28="Must",3,IF(C28="Should",2,IF(C28="Could",1,0))) | E28: OOTB | F28: 3.3 | G28: Ano | H28: =IF(E28="","",IF(OR(AND(OR(E28="OOTB",E28="Konfigurace",E28="Custom vývoj"),F28=""),G28="Ne"),0,IF(E28="OOTB",5,IF(E28="Konfigurace",3,IF(E28="Custom vývoj",1,0))))) | I28: 3rd party | L28: =IF(I28="","",IF(OR(AND(OR(I28="OOTB",I28="Konfigurace",I28="Custom vývoj"),J28=""),K28="Ne"),0,IF(I28="OOTB",5,IF(I28="Konfigurace",3,IF(I28="Custom vývoj",1,0))))) | M28: OOTB | N28: 3.3 | O28: Ano | P28: =IF(M28="","",IF(OR(AND(OR(M28="OOTB",M28="Konfigurace",M28="Custom vývoj"),N28=""),O28="Ne"),0,IF(M28="OOTB",5,IF(M28="Konfigurace",3,IF(M28="Custom vývoj",1,0)))))
A29: SCR-010 | B29: Uchování historie screeningu (verze seznamu, výsledek, rozhodnutí, uživatel) po dobu 10 let od ukončení obchodního vztahu. | C29: Must | D29: =IF(C29="Must",3,IF(C29="Should",2,IF(C29="Could",1,0))) | E29: Konfigurace | F29: 9.2 | G29: Ano | H29: =IF(E29="","",IF(OR(AND(OR(E29="OOTB",E29="Konfigurace",E29="Custom vývoj"),F29=""),G29="Ne"),0,IF(E29="OOTB",5,IF(E29="Konfigurace",3,IF(E29="Custom vývoj",1,0))))) | I29: OOTB | J29: 9.2 | K29: Ano | L29: =IF(I29="","",IF(OR(AND(OR(I29="OOTB",I29="Konfigurace",I29="Custom vývoj"),J29=""),K29="Ne"),0,IF(I29="OOTB",5,IF(I29="Konfigurace",3,IF(I29="Custom vývoj",1,0))))) | M29: OOTB | N29: 9.2 | O29: Ano | P29: =IF(M29="","",IF(OR(AND(OR(M29="OOTB",M29="Konfigurace",M29="Custom vývoj"),N29=""),O29="Ne"),0,IF(M29="OOTB",5,IF(M29="Konfigurace",3,IF(M29="Custom vývoj",1,0)))))
A30: TM-001 | B30: Monitoring transakcí pomocí konfigurovatelných scénářů; dodávaná knihovna obsahuje min. 40 typologií relevantních pro privátní bankovnictví (strukturování, rychlý průtok, rizikové země, nesoulad s profilem). | C30: Must | D30: =IF(C30="Must",3,IF(C30="Should",2,IF(C30="Could",1,0))) | E30: Konfigurace | F30: 6.3 | G30: Ano | H30: =IF(E30="","",IF(OR(AND(OR(E30="OOTB",E30="Konfigurace",E30="Custom vývoj"),F30=""),G30="Ne"),0,IF(E30="OOTB",5,IF(E30="Konfigurace",3,IF(E30="Custom vývoj",1,0))))) | I30: OOTB | J30: 6.3 | K30: Ano | L30: =IF(I30="","",IF(OR(AND(OR(I30="OOTB",I30="Konfigurace",I30="Custom vývoj"),J30=""),K30="Ne"),0,IF(I30="OOTB",5,IF(I30="Konfigurace",3,IF(I30="Custom vývoj",1,0))))) | M30: OOTB | N30: 6.3 | O30: Ano | P30: =IF(M30="","",IF(OR(AND(OR(M30="OOTB",M30="Konfigurace",M30="Custom vývoj"),N30=""),O30="Ne"),0,IF(M30="OOTB",5,IF(M30="Konfigurace",3,IF(M30="Custom vývoj",1,0)))))
A31: TM-002 | B31: Compliance vytváří a mění scénáře v UI bez vývoje dodavatele; změny se verzují a schvalují čtyřma očima. | C31: Must | D31: =IF(C31="Must",3,IF(C31="Should",2,IF(C31="Could",1,0))) | E31: Konfigurace | F31: 6.3 | G31: Ano | H31: =IF(E31="","",IF(OR(AND(OR(E31="OOTB",E31="Konfigurace",E31="Custom vývoj"),F31=""),G31="Ne"),0,IF(E31="OOTB",5,IF(E31="Konfigurace",3,IF(E31="Custom vývoj",1,0))))) | I31: Custom vývoj | K31: Ano | L31: =IF(I31="","",IF(OR(AND(OR(I31="OOTB",I31="Konfigurace",I31="Custom vývoj"),J31=""),K31="Ne"),0,IF(I31="OOTB",5,IF(I31="Konfigurace",3,IF(I31="Custom vývoj",1,0))))) | M31: OOTB | N31: 6.3 | O31: Ano | P31: =IF(M31="","",IF(OR(AND(OR(M31="OOTB",M31="Konfigurace",M31="Custom vývoj"),N31=""),O31="Ne"),0,IF(M31="OOTB",5,IF(M31="Konfigurace",3,IF(M31="Custom vývoj",1,0))))) | Q31: Dodavatel B: Chybí odkaz do FS – dle pravidla křížové kontroly nesplněno.
A32: TM-003 | B32: Testování (backtesting) nového nebo upraveného scénáře nad historickými daty před nasazením. | C32: Should | D32: =IF(C32="Must",3,IF(C32="Should",2,IF(C32="Could",1,0))) | E32: OOTB | F32: 6.3 | G32: Ano | H32: =IF(E32="","",IF(OR(AND(OR(E32="OOTB",E32="Konfigurace",E32="Custom vývoj"),F32=""),G32="Ne"),0,IF(E32="OOTB",5,IF(E32="Konfigurace",3,IF(E32="Custom vývoj",1,0))))) | I32: Konfigurace | J32: 6.3 | K32: Ano | L32: =IF(I32="","",IF(OR(AND(OR(I32="OOTB",I32="Konfigurace",I32="Custom vývoj"),J32=""),K32="Ne"),0,IF(I32="OOTB",5,IF(I32="Konfigurace",3,IF(I32="Custom vývoj",1,0))))) | M32: OOTB | N32: 6.3 | O32: Ano | P32: =IF(M32="","",IF(OR(AND(OR(M32="OOTB",M32="Konfigurace",M32="Custom vývoj"),N32=""),O32="Ne"),0,IF(M32="OOTB",5,IF(M32="Konfigurace",3,IF(M32="Custom vývoj",1,0)))))
A33: TM-004 | B33: Kontrola úplnosti informací o plátci a příjemci u bezhotovostních převodů a hlášení neúplných zpráv. | C33: Should | D33: =IF(C33="Must",3,IF(C33="Should",2,IF(C33="Could",1,0))) | E33: Konfigurace | F33: 6.3 | G33: Ano | H33: =IF(E33="","",IF(OR(AND(OR(E33="OOTB",E33="Konfigurace",E33="Custom vývoj"),F33=""),G33="Ne"),0,IF(E33="OOTB",5,IF(E33="Konfigurace",3,IF(E33="Custom vývoj",1,0))))) | I33: Konfigurace | J33: 6.3 | K33: Ano | L33: =IF(I33="","",IF(OR(AND(OR(I33="OOTB",I33="Konfigurace",I33="Custom vývoj"),J33=""),K33="Ne"),0,IF(I33="OOTB",5,IF(I33="Konfigurace",3,IF(I33="Custom vývoj",1,0))))) | M33: OOTB | N33: 6.3 | O33: Ano | P33: =IF(M33="","",IF(OR(AND(OR(M33="OOTB",M33="Konfigurace",M33="Custom vývoj"),N33=""),O33="Ne"),0,IF(M33="OOTB",5,IF(M33="Konfigurace",3,IF(M33="Custom vývoj",1,0)))))
A34: TM-005 | B34: Profil očekávaného chování klienta (obrat, země, typy transakcí dle KYC) a alert při významné odchylce skutečnosti od profilu. | C34: Must | D34: =IF(C34="Must",3,IF(C34="Should",2,IF(C34="Could",1,0))) | E34: Konfigurace | F34: 6.3 | G34: Ano | H34: =IF(E34="","",IF(OR(AND(OR(E34="OOTB",E34="Konfigurace",E34="Custom vývoj"),F34=""),G34="Ne"),0,IF(E34="OOTB",5,IF(E34="Konfigurace",3,IF(E34="Custom vývoj",1,0))))) | I34: Konfigurace | J34: 6.3 | K34: Ano | L34: =IF(I34="","",IF(OR(AND(OR(I34="OOTB",I34="Konfigurace",I34="Custom vývoj"),J34=""),K34="Ne"),0,IF(I34="OOTB",5,IF(I34="Konfigurace",3,IF(I34="Custom vývoj",1,0))))) | M34: OOTB | N34: 6.3 | O34: Ano | P34: =IF(M34="","",IF(OR(AND(OR(M34="OOTB",M34="Konfigurace",M34="Custom vývoj"),N34=""),O34="Ne"),0,IF(M34="OOTB",5,IF(M34="Konfigurace",3,IF(M34="Custom vývoj",1,0)))))
A35: TM-006 | B35: Podpora odkladu splnění příkazu klienta: pozastavení odchozí platby na základě alertu a evidence lhůt odkladu. | C35: Must | D35: =IF(C35="Must",3,IF(C35="Should",2,IF(C35="Could",1,0))) | E35: OOTB | F35: 5.4 | G35: Ano | H35: =IF(E35="","",IF(OR(AND(OR(E35="OOTB",E35="Konfigurace",E35="Custom vývoj"),F35=""),G35="Ne"),0,IF(E35="OOTB",5,IF(E35="Konfigurace",3,IF(E35="Custom vývoj",1,0))))) | I35: OOTB | J35: 5.4 | K35: Ano | L35: =IF(I35="","",IF(OR(AND(OR(I35="OOTB",I35="Konfigurace",I35="Custom vývoj"),J35=""),K35="Ne"),0,IF(I35="OOTB",5,IF(I35="Konfigurace",3,IF(I35="Custom vývoj",1,0))))) | M35: OOTB | N35: 5.4 | O35: Ano | P35: =IF(M35="","",IF(OR(AND(OR(M35="OOTB",M35="Konfigurace",M35="Custom vývoj"),N35=""),O35="Ne"),0,IF(M35="OOTB",5,IF(M35="Konfigurace",3,IF(M35="Custom vývoj",1,0)))))
A36: TM-007 | B36: Detekce anomálií pomocí strojového učení jako doplněk scénářů, s vysvětlením důvodu alertu srozumitelným pro analytika. | C36: Could | D36: =IF(C36="Must",3,IF(C36="Should",2,IF(C36="Could",1,0))) | E36: Custom vývoj | F36: 6.6 | G36: Ano | H36: =IF(E36="","",IF(OR(AND(OR(E36="OOTB",E36="Konfigurace",E36="Custom vývoj"),F36=""),G36="Ne"),0,IF(E36="OOTB",5,IF(E36="Konfigurace",3,IF(E36="Custom vývoj",1,0))))) | I36: Konfigurace | J36: 6.3 | K36: Ano | L36: =IF(I36="","",IF(OR(AND(OR(I36="OOTB",I36="Konfigurace",I36="Custom vývoj"),J36=""),K36="Ne"),0,IF(I36="OOTB",5,IF(I36="Konfigurace",3,IF(I36="Custom vývoj",1,0))))) | M36: Custom vývoj | N36: 6.6 | O36: Ano | P36: =IF(M36="","",IF(OR(AND(OR(M36="OOTB",M36="Konfigurace",M36="Custom vývoj"),N36=""),O36="Ne"),0,IF(M36="OOTB",5,IF(M36="Konfigurace",3,IF(M36="Custom vývoj",1,0)))))
A37: TM-008 | B37: Při spuštění systém zpracuje transakční historii za 24 měsíců pro výpočet profilů a baseline scénářů. | C37: Should | D37: =IF(C37="Must",3,IF(C37="Should",2,IF(C37="Could",1,0))) | E37: OOTB | F37: 7.2 | G37: Ano | H37: =IF(E37="","",IF(OR(AND(OR(E37="OOTB",E37="Konfigurace",E37="Custom vývoj"),F37=""),G37="Ne"),0,IF(E37="OOTB",5,IF(E37="Konfigurace",3,IF(E37="Custom vývoj",1,0))))) | I37: OOTB | J37: 7.2 | K37: Ano | L37: =IF(I37="","",IF(OR(AND(OR(I37="OOTB",I37="Konfigurace",I37="Custom vývoj"),J37=""),K37="Ne"),0,IF(I37="OOTB",5,IF(I37="Konfigurace",3,IF(I37="Custom vývoj",1,0))))) | M37: OOTB | N37: 7.2 | O37: Ano | P37: =IF(M37="","",IF(OR(AND(OR(M37="OOTB",M37="Konfigurace",M37="Custom vývoj"),N37=""),O37="Ne"),0,IF(M37="OOTB",5,IF(M37="Konfigurace",3,IF(M37="Custom vývoj",1,0)))))
A38: CAS-001 | B38: Jednotná správa případů pro alerty ze screeningu, monitoringu transakcí a KYC, s prioritizací, přidělováním a sledováním lhůt zpracování. | C38: Must | D38: =IF(C38="Must",3,IF(C38="Should",2,IF(C38="Could",1,0))) | E38: Konfigurace | F38: 6.4 | G38: Ano | H38: =IF(E38="","",IF(OR(AND(OR(E38="OOTB",E38="Konfigurace",E38="Custom vývoj"),F38=""),G38="Ne"),0,IF(E38="OOTB",5,IF(E38="Konfigurace",3,IF(E38="Custom vývoj",1,0))))) | I38: OOTB | J38: 6.4 | K38: Ano | L38: =IF(I38="","",IF(OR(AND(OR(I38="OOTB",I38="Konfigurace",I38="Custom vývoj"),J38=""),K38="Ne"),0,IF(I38="OOTB",5,IF(I38="Konfigurace",3,IF(I38="Custom vývoj",1,0))))) | M38: Konfigurace | N38: 6.4 | O38: Ano | P38: =IF(M38="","",IF(OR(AND(OR(M38="OOTB",M38="Konfigurace",M38="Custom vývoj"),N38=""),O38="Ne"),0,IF(M38="OOTB",5,IF(M38="Konfigurace",3,IF(M38="Custom vývoj",1,0)))))
A39: CAS-002 | B39: Rozhodnutí o přijetí, zamítnutí, blokaci nebo ukončení vztahu probíhá na principu čtyř očí; systém nedovolí, aby rozhodl uživatel, který případ připravil. | C39: Must | D39: =IF(C39="Must",3,IF(C39="Should",2,IF(C39="Could",1,0))) | E39: OOTB | F39: 6.4 | G39: Ano | H39: =IF(E39="","",IF(OR(AND(OR(E39="OOTB",E39="Konfigurace",E39="Custom vývoj"),F39=""),G39="Ne"),0,IF(E39="OOTB",5,IF(E39="Konfigurace",3,IF(E39="Custom vývoj",1,0))))) | I39: Konfigurace | J39: 6.4 | K39: Ano | L39: =IF(I39="","",IF(OR(AND(OR(I39="OOTB",I39="Konfigurace",I39="Custom vývoj"),J39=""),K39="Ne"),0,IF(I39="OOTB",5,IF(I39="Konfigurace",3,IF(I39="Custom vývoj",1,0))))) | M39: Konfigurace | N39: 6.4 | O39: Ano | P39: =IF(M39="","",IF(OR(AND(OR(M39="OOTB",M39="Konfigurace",M39="Custom vývoj"),N39=""),O39="Ne"),0,IF(M39="OOTB",5,IF(M39="Konfigurace",3,IF(M39="Custom vývoj",1,0)))))
A40: CAS-003 | B40: Rozhodnutí se do 1 minuty propíše do CRM jako stav klienta (aktivní / v prověření / blokován / ukončen) a CRM podle stavu omezí dostupné akce. | C40: Must | D40: =IF(C40="Must",3,IF(C40="Should",2,IF(C40="Could",1,0))) | E40: Konfigurace | F40: 5.1 | G40: Ano | H40: =IF(E40="","",IF(OR(AND(OR(E40="OOTB",E40="Konfigurace",E40="Custom vývoj"),F40=""),G40="Ne"),0,IF(E40="OOTB",5,IF(E40="Konfigurace",3,IF(E40="Custom vývoj",1,0))))) | I40: OOTB | J40: 5.1 | K40: Ano | L40: =IF(I40="","",IF(OR(AND(OR(I40="OOTB",I40="Konfigurace",I40="Custom vývoj"),J40=""),K40="Ne"),0,IF(I40="OOTB",5,IF(I40="Konfigurace",3,IF(I40="Custom vývoj",1,0))))) | M40: OOTB | N40: 5.1 | O40: Ano | P40: =IF(M40="","",IF(OR(AND(OR(M40="OOTB",M40="Konfigurace",M40="Custom vývoj"),N40=""),O40="Ne"),0,IF(M40="OOTB",5,IF(M40="Konfigurace",3,IF(M40="Custom vývoj",1,0)))))
A41: CAS-004 | B41: Zamítnutí nebo blokaci klienta vždy potvrzuje člověk; plně automatické rozhodnutí je možné jen v předem schválených případech (např. přesná shoda se sankčním seznamem). | C41: Must | D41: =IF(C41="Must",3,IF(C41="Should",2,IF(C41="Could",1,0))) | E41: OOTB | F41: 6.4 | G41: Ano | H41: =IF(E41="","",IF(OR(AND(OR(E41="OOTB",E41="Konfigurace",E41="Custom vývoj"),F41=""),G41="Ne"),0,IF(E41="OOTB",5,IF(E41="Konfigurace",3,IF(E41="Custom vývoj",1,0))))) | I41: Konfigurace | J41: 6.4 | K41: Ano | L41: =IF(I41="","",IF(OR(AND(OR(I41="OOTB",I41="Konfigurace",I41="Custom vývoj"),J41=""),K41="Ne"),0,IF(I41="OOTB",5,IF(I41="Konfigurace",3,IF(I41="Custom vývoj",1,0))))) | M41: OOTB | N41: 6.4 | O41: Ano | P41: =IF(M41="","",IF(OR(AND(OR(M41="OOTB",M41="Konfigurace",M41="Custom vývoj"),N41=""),O41="Ne"),0,IF(M41="OOTB",5,IF(M41="Konfigurace",3,IF(M41="Custom vývoj",1,0)))))
...

Sheet 3_Arch_Sec
A1: 3 – Architektura a bezpečnost (20 %) – hodnocení Feasibility Study, škála 0–10
A2: Horizont Privátní banka, a.s. · Projekt SENTINEL – výměna KYC/AML řešení
A3: FIKTIVNÍ CVIČNÝ DOKUMENT – banka, osoby a dodavatelé jsou smyšlení.
A5: Dodavatel | B5: Kritérium (kapitola FS) | C5: Popis | D5: Ing. Jana Novotná | E5: Ing. Martin Dvořák | F5: Mgr. Tomáš Svoboda | G5: JUDr. Lucie Malá | H5: Průměr | I5: Průměr kritéria (všichni dodavatelé) | J5: Zdůvodnění (povinné u známky pod průměrem kritéria) | K5: Kontrola
A6: Dodavatel A | B6: FS 3 | C6: Návrh cílové architektury (hosting, DB, HA/DR, sizing) | D6: 9 | E6: 8 | F6: 8 | G6: 8 | H6: =AVERAGE(D6:G6) | I6: =AVERAGE(D6:G6,D12:G12,D18:G18) | K6: =IF(AND(MIN(D6:G6)<I6,J6=""),"DOPLNIT ZDŮVODNĚNÍ","OK")
A7: Dodavatel A | B7: FS 4 | C7: Bezpečnostní koncept (role, šifrování, logování, zranitelnosti, pentesty) | D7: 8 | E7: 9 | F7: 8 | G7: 8 | H7: =AVERAGE(D7:G7) | I7: =AVERAGE(D7:G7,D13:G13,D19:G19) | K7: =IF(AND(MIN(D7:G7)<I7,J7=""),"DOPLNIT ZDŮVODNĚNÍ","OK")
A8: Dodavatel A | B8: FS 5 | C8: Řešení kritických integrací (CRM, core přes Kafka, platby, DWH) | D8: 8 | E8: 8 | F8: 9 | G8: 8 | H8: =AVERAGE(D8:G8) | I8: =AVERAGE(D8:G8,D14:G14,D20:G20) | K8: =IF(AND(MIN(D8:G8)<I8,J8=""),"DOPLNIT ZDŮVODNĚNÍ","OK")
A9: Dodavatel A | B9: FS 6.6 | C9: Řešení custom požadavků | D9: 7 | E9: 7 | F9: 8 | G9: 7 | H9: =AVERAGE(D9:G9) | I9: =AVERAGE(D9:G9,D15:G15,D21:G21) | K9: =IF(AND(MIN(D9:G9)<I9,J9=""),"DOPLNIT ZDŮVODNĚNÍ","OK")
A10: Dodavatel A | B10: FS 7 | C10: Plán implementace a migrace bez výpadku | D10: 8 | E10: 8 | F10: 8 | G10: 9 | H10: =AVERAGE(D10:G10) | I10: =AVERAGE(D10:G10,D16:G16,D22:G22) | K10: =IF(AND(MIN(D10:G10)<I10,J10=""),"DOPLNIT ZDŮVODNĚNÍ","OK")
A11: Dodavatel A | B11: FS 9–10 | C11: Regulatorní soulad, auditovatelnost a exit strategie | D11: 8 | E11: 8 | F11: 9 | G11: 9 | H11: =AVERAGE(D11:G11) | I11: =AVERAGE(D11:G11,D17:G17,D23:G23) | K11: =IF(AND(MIN(D11:G11)<I11,J11=""),"DOPLNIT ZDŮVODNĚNÍ","OK")
A12: Dodavatel B | B12: FS 3 | C12: Návrh cílové architektury (hosting, DB, HA/DR, sizing) | D12: 7 | E12: 7 | F12: 7 | G12: 7 | H12: =AVERAGE(D12:G12) | I12: =AVERAGE(D6:G6,D12:G12,D18:G18) | J12: Sizing HW uveden jen pro PROD, chybí PreProd a DR. | K12: =IF(AND(MIN(D12:G12)<I12,J12=""),"DOPLNIT ZDŮVODNĚNÍ","OK")
A13: Dodavatel B | B13: FS 4 | C13: Bezpečnostní koncept (role, šifrování, logování, zranitelnosti, pentesty) | D13: 6 | E13: 5 | F13: 6 | G13: 7 | H13: =AVERAGE(D13:G13) | I13: =AVERAGE(D7:G7,D13:G13,D19:G19) | J13: Správa šifrovacích klíčů u dodavatele, ne v HSM Banky; chybí harmonogram penetračních testů. | K13: =IF(AND(MIN(D13:G13)<I13,J13=""),"DOPLNIT ZDŮVODNĚNÍ","OK")
A14: Dodavatel B | B14: FS 5 | C14: Řešení kritických integrací (CRM, core přes Kafka, platby, DWH) | D14: 5 | E14: 6 | F14: 6 | G14: 6 | H14: =AVERAGE(D14:G14) | I14: =AVERAGE(D8:G8,D14:G14,D20:G20) | J14: Dodavatel navrhuje point-to-point integraci na core banking namísto požadované bankovní Kafka sběrnice. | K14: =IF(AND(MIN(D14:G14)<I14,J14=""),"DOPLNIT ZDŮVODNĚNÍ","OK")
A15: Dodavatel B | B15: FS 6.6 | C15: Řešení custom požadavků | D15: 6 | E15: 6 | F15: 6 | G15: 5 | H15: =AVERAGE(D15:G15) | I15: =AVERAGE(D9:G9,D15:G15,D21:G21) | J15: Custom vývoj popsán obecně bez odhadu pracnosti a dopadu na upgrady. | K15: =IF(AND(MIN(D15:G15)<I15,J15=""),"DOPLNIT ZDŮVODNĚNÍ","OK")
A16: Dodavatel B | B16: FS 7 | C16: Plán implementace a migrace bez výpadku | D16: 7 | E16: 7 | F16: 6 | G16: 7 | H16: =AVERAGE(D16:G16) | I16: =AVERAGE(D10:G10,D16:G16,D22:G22) | J16: Paralelní provoz jen 2 týdny a bez popsané rekonciliace historie případů. | K16: =IF(AND(MIN(D16:G16)<I16,J16=""),"DOPLNIT ZDŮVODNĚNÍ","OK")
A17: Dodavatel B | B17: FS 9–10 | C17: Regulatorní soulad, auditovatelnost a exit strategie | D17: 6 | E17: 6 | F17: 7 | G17: 6 | H17: =AVERAGE(D17:G17) | I17: =AVERAGE(D11:G11,D17:G17,D23:G23) | J17: Exit plán neřeší export auditních stop a historie screeningu. | K17: =IF(AND(MIN(D17:G17)<I17,J17=""),"DOPLNIT ZDŮVODNĚNÍ","OK")
A18: Dodavatel C | B18: FS 3 | C18: Návrh cílové architektury (hosting, DB, HA/DR, sizing) | D18: 8 | E18: 7 | F18: 8 | G18: 8 | H18: =AVERAGE(D18:G18) | I18: =AVERAGE(D6:G6,D12:G12,D18:G18) | J18: Architektura počítá se sdílenou multi-tenant platformou, privátní instance jen jako příplatková varianta. | K18: =IF(AND(MIN(D18:G18)<I18,J18=""),"DOPLNIT ZDŮVODNĚNÍ","OK")
A19: Dodavatel C | B19: FS 4 | C19: Bezpečnostní koncept (role, šifrování, logování, zranitelnosti, pentesty) | D19: 7 | E19: 6 | F19: 7 | G19: 7 | H19: =AVERAGE(D19:G19) | I19: =AVERAGE(D7:G7,D13:G13,D19:G19) | J19: Privilegovaný přístup podpory z třetí země není řešen přes PAM Banky. | K19: =IF(AND(MIN(D19:G19)<I19,J19=""),"DOPLNIT ZDŮVODNĚNÍ","OK")
A20: Dodavatel C | B20: FS 5 | C20: Řešení kritických integrací (CRM, core přes Kafka, platby, DWH) | D20: 8 | E20: 7 | F20: 8 | G20: 8 | H20: =AVERAGE(D20:G20) | I20: =AVERAGE(D8:G8,D14:G14,D20:G20) | J20: Integrace na CRM popsána obecně přes standardní konektor, chybí řešení událostí pro změny stavu klienta. | K20: =IF(AND(MIN(D20:G20)<I20,J20=""),"DOPLNIT ZDŮVODNĚNÍ","OK")
A21: Dodavatel C | B21: FS 6.6 | C21: Řešení custom požadavků | D21: 8 | E21: 8 | F21: 8 | G21: 8 | H21: =AVERAGE(D21:G21) | I21: =AVERAGE(D9:G9,D15:G15,D21:G21) | K21: =IF(AND(MIN(D21:G21)<I21,J21=""),"DOPLNIT ZDŮVODNĚNÍ","OK")
A22: Dodavatel C | B22: FS 7 | C22: Plán implementace a migrace bez výpadku | D22: 7 | E22: 7 | F22: 7 | G22: 7 | H22: =AVERAGE(D22:G22) | I22: =AVERAGE(D10:G10,D16:G16,D22:G22) | J22: Migrace historie screeningu jen za 5 let, zbytek jako archiv v PDF – nesplňuje § 16 AML zákona. | K22: =IF(AND(MIN(D22:G22)<I22,J22=""),"DOPLNIT ZDŮVODNĚNÍ","OK")
A23: Dodavatel C | B23: FS 9–10 | C23: Regulatorní soulad, auditovatelnost a exit strategie | D23: 5 | E23: 4 | F23: 5 | G23: 4 | H23: =AVERAGE(D23:G23) | I23: =AVERAGE(D11:G11,D17:G17,D23:G23) | J23: Zálohy mimo EU/EHP a nejasné subdodavatelské řetězení podpory; exit bez exportu konfigurace. | K23: =IF(AND(MIN(D23:G23)<I23,J23=""),"DOPLNIT ZDŮVODNĚNÍ","OK")
A25: Výsledek
A26: Dodavatel | B26: Průměrná známka | C26: Body (max. 20)
A27: Dodavatel A | B27: =AVERAGE(H6:H11) | C27: =B27/10*Parametry!$B$8*100
A28: Dodavatel B | B28: =AVERAGE(H12:H17) | C28: =B28/10*Parametry!$B$8*100
A29: Dodavatel C | B29: =AVERAGE(H18:H23) | C29: =B29/10*Parametry!$B$8*100

Sheet 4_Delivery
A1: 4 – Delivery a zkušenosti (10 %), škála 0–10
A2: Horizont Privátní banka, a.s. · Projekt SENTINEL – výměna KYC/AML řešení
A3: FIKTIVNÍ CVIČNÝ DOKUMENT – banka, osoby a dodavatelé jsou smyšlení.
A5: Dodavatel | B5: Kritérium | C5: Popis | D5: Ing. Jana Novotná | E5: Ing. Martin Dvořák | F5: Mgr. Tomáš Svoboda | G5: JUDr. Lucie Malá | H5: Průměr | I5: Průměr kritéria | J5: Zdůvodnění | K5: Kontrola
A6: Dodavatel A | B6: D1 | C6: Reference z finančního sektoru (min. 2 banky v EU s AML řešením v produkci) | D6: 9 | E6: 8 | F6: 8 | G6: 9 | H6: =AVERAGE(D6:G6) | I6: =AVERAGE(D6:G6,D10:G10,D14:G14) | J6: Dvě reference z bank v EU, ale žádná z ČR – chybí přímá zkušenost s požadavky ČNB a FAÚ. | K6: =IF(AND(MIN(D6:G6)<I6,J6=""),"DOPLNIT ZDŮVODNĚNÍ","OK")
A7: Dodavatel A | B7: D2 | C7: Seniorita klíčových osob (CV: PM, architekt, AML konzultant, vedoucí migrace) | D7: 8 | E7: 8 | F7: 7 | G7: 8 | H7: =AVERAGE(D7:G7) | I7: =AVERAGE(D7:G7,D11:G11,D15:G15) | J7: Vedoucí migrace má méně než 3 roky praxe s migrací AML dat. | K7: =IF(AND(MIN(D7:G7)<I7,J7=""),"DOPLNIT ZDŮVODNĚNÍ","OK")
A8: Dodavatel A | B8: D3 | C8: Návrh SLA a podpory vs. Příloha 4 (odchylky, sankce, RCA) | D8: 7 | E8: 7 | F8: 8 | G8: 7 | H8: =AVERAGE(D8:G8) | I8: =AVERAGE(D8:G8,D12:G12,D16:G16) | J8: Navrhuje cap sankcí 15 % ročního poplatku, Banka požaduje min. 30 %. | K8: =IF(AND(MIN(D8:G8)<I8,J8=""),"DOPLNIT ZDŮVODNĚNÍ","OK")
A9: Dodavatel A | B9: D4 | C9: Realističnost projektového plánu a kapacit | D9: 8 | E9: 8 | F9: 8 | G9: 8 | H9: =AVERAGE(D9:G9) | I9: =AVERAGE(D9:G9,D13:G13,D17:G17) | K9: =IF(AND(MIN(D9:G9)<I9,J9=""),"DOPLNIT ZDŮVODNĚNÍ","OK")
A10: Dodavatel B | B10: D1 | C10: Reference z finančního sektoru (min. 2 banky v EU s AML řešením v produkci) | D10: 8 | E10: 8 | F10: 8 | G10: 8 | H10: =AVERAGE(D10:G10) | I10: =AVERAGE(D6:G6,D10:G10,D14:G14) | J10: Reference pouze z retailových bank, žádná z privátního bankovnictví. | K10: =IF(AND(MIN(D10:G10)<I10,J10=""),"DOPLNIT ZDŮVODNĚNÍ","OK")
A11: Dodavatel B | B11: D2 | C11: Seniorita klíčových osob (CV: PM, architekt, AML konzultant, vedoucí migrace) | D11: 7 | E11: 7 | F11: 7 | G11: 8 | H11: =AVERAGE(D11:G11) | I11: =AVERAGE(D7:G7,D11:G11,D15:G15) | J11: Navržený solution architekt nemá zkušenost s integrací přes Kafka. | K11: =IF(AND(MIN(D11:G11)<I11,J11=""),"DOPLNIT ZDŮVODNĚNÍ","OK")
A12: Dodavatel B | B12: D3 | C12: Návrh SLA a podpory vs. Příloha 4 (odchylky, sankce, RCA) | D12: 8 | E12: 8 | F12: 7 | G12: 8 | H12: =AVERAGE(D12:G12) | I12: =AVERAGE(D8:G8,D12:G12,D16:G16) | K12: =IF(AND(MIN(D12:G12)<I12,J12=""),"DOPLNIT ZDŮVODNĚNÍ","OK")
A13: Dodavatel B | B13: D4 | C13: Realističnost projektového plánu a kapacit | D13: 6 | E13: 7 | F13: 6 | G13: 6 | H13: =AVERAGE(D13:G13) | I13: =AVERAGE(D9:G9,D13:G13,D17:G17) | J13: Plán počítá s paralelním provozem jen 2 týdny místo požadovaných 4. | K13: =IF(AND(MIN(D13:G13)<I13,J13=""),"DOPLNIT ZDŮVODNĚNÍ","OK")
A14: Dodavatel C | B14: D1 | C14: Reference z finančního sektoru (min. 2 banky v EU s AML řešením v produkci) | D14: 9 | E14: 9 | F14: 8 | G14: 9 | H14: =AVERAGE(D14:G14) | I14: =AVERAGE(D6:G6,D10:G10,D14:G14) | J14: Jedna ze dvou referencí je platební instituce, nikoli banka. | K14: =IF(AND(MIN(D14:G14)<I14,J14=""),"DOPLNIT ZDŮVODNĚNÍ","OK")
A15: Dodavatel C | B15: D2 | C15: Seniorita klíčových osob (CV: PM, architekt, AML konzultant, vedoucí migrace) | D15: 7 | E15: 7 | F15: 7 | G15: 7 | H15: =AVERAGE(D15:G15) | I15: =AVERAGE(D7:G7,D11:G11,D15:G15) | J15: CV dvou klíčových osob jsou od subdodavatele a neodpovídají týmu v projektovém plánu. | K15: =IF(AND(MIN(D15:G15)<I15,J15=""),"DOPLNIT ZDŮVODNĚNÍ","OK")
A16: Dodavatel C | B16: D3 | C16: Návrh SLA a podpory vs. Příloha 4 (odchylky, sankce, RCA) | D16: 5 | E16: 5 | F16: 4 | G16: 5 | H16: =AVERAGE(D16:G16) | I16: =AVERAGE(D8:G8,D12:G12,D16:G16) | J16: SLA měří dostupnost infrastruktury, ne byznys transakcí; cap sankcí 5 % ročního poplatku. | K16: =IF(AND(MIN(D16:G16)<I16,J16=""),"DOPLNIT ZDŮVODNĚNÍ","OK")
A17: Dodavatel C | B17: D4 | C17: Realističnost projektového plánu a kapacit | D17: 7 | E17: 7 | F17: 7 | G17: 7 | H17: =AVERAGE(D17:G17) | I17: =AVERAGE(D9:G9,D13:G13,D17:G17) | J17: Plán nemá rezervu na UAT obchodu ani na opakované zkušební migrace. | K17: =IF(AND(MIN(D17:G17)<I17,J17=""),"DOPLNIT ZDŮVODNĚNÍ","OK")
A20: Dodavatel | B20: Průměrná známka | C20: Body (max. 10)
A21: Dodavatel A | B21: =AVERAGE(H6:H9) | C21: =B21/10*Parametry!$B$9*100
A22: Dodavatel B | B22: =AVERAGE(H10:H13) | C22: =B22/10*Parametry!$B$9*100
A23: Dodavatel C | B23: =AVERAGE(H14:H17) | C23: =B23/10*Parametry!$B$9*100

Sheet 5_Cena
A1: 5 – Cena (40 %): TCO na 5 let z Přílohy 3 (po BAFO)
A2: Horizont Privátní banka, a.s. · Projekt SENTINEL – výměna KYC/AML řešení
A3: FIKTIVNÍ CVIČNÝ DOKUMENT – banka, osoby a dodavatelé jsou smyšlení.
A5: Dodavatel | B5: TCO 5 let (Kč bez DPH) | C5: Stav K.O. brány | D5: TCO do výpočtu | E5: Body (max. 40) | F5: Poznámka
A6: Dodavatel A | B6: 52400000 | C6: ='1_KO_brana'!D17 | D6: =IF(C6="POSTUPUJE",B6,"") | E6: =IF(D6="","",MIN($D$6:$D$8)/D6*Parametry!$B$6*100) | F6: Po BAFO sleva 6 % na licence; datové feedy PEP oceněny na 5 let.
A7: Dodavatel B | B7: 41900000 | C7: ='1_KO_brana'!E17 | D7: =IF(C7="POSTUPUJE",B7,"") | E7: =IF(D7="","",MIN($D$6:$D$8)/D7*Parametry!$B$6*100) | F7: Nízká cena licence; 24 požadavků jako Custom vývoj zvyšuje riziko víceprací.
A8: Dodavatel C | B8: 46300000 | C8: ='1_KO_brana'!F17 | D8: =IF(C8="POSTUPUJE",B8,"") | E8: =IF(D8="","",MIN($D$6:$D$8)/D8*Parametry!$B$6*100) | F8: Vyřazen v K.O. bráně – cena se nehodnotí.

Sheet Vysledek
A1: Výsledek hodnocení
A2: Horizont Privátní banka, a.s. · Projekt SENTINEL – výměna KYC/AML řešení
A3: FIKTIVNÍ CVIČNÝ DOKUMENT – banka, osoby a dodavatelé jsou smyšlení.
A5: Dodavatel | B5: K.O. brána | C5: Cena (40) | D5: Byznys (30) | E5: Arch & Sec (20) | F5: Delivery (10) | G5: Celkem (100) | H5: Pořadí
A6: Dodavatel A | B6: ='1_KO_brana'!D17 | C6: =IF(B6="POSTUPUJE",'5_Cena'!E6,"") | D6: =IF(B6="POSTUPUJE",'2_Byznys'!H52,"") | E6: =IF(B6="POSTUPUJE",'3_Arch_Sec'!C27,"") | F6: =IF(B6="POSTUPUJE",'4_Delivery'!C21,"") | G6: =IF(B6="POSTUPUJE",SUM(C6:F6),"vyřazen") | H6: =IF(ISNUMBER(G6),RANK(G6,$G$6:$G$8),"–")
A7: Dodavatel B | B7: ='1_KO_brana'!E17 | C7: =IF(B7="POSTUPUJE",'5_Cena'!E7,"") | D7: =IF(B7="POSTUPUJE",'2_Byznys'!L52,"") | E7: =IF(B7="POSTUPUJE",'3_Arch_Sec'!C28,"") | F7: =IF(B7="POSTUPUJE",'4_Delivery'!C22,"") | G7: =IF(B7="POSTUPUJE",SUM(C7:F7),"vyřazen") | H7: =IF(ISNUMBER(G7),RANK(G7,$G$6:$G$8),"–")
A8: Dodavatel C | B8: ='1_KO_brana'!F17 | C8: =IF(B8="POSTUPUJE",'5_Cena'!E8,"") | D8: =IF(B8="POSTUPUJE",'2_Byznys'!P52,"") | E8: =IF(B8="POSTUPUJE",'3_Arch_Sec'!C29,"") | F8: =IF(B8="POSTUPUJE",'4_Delivery'!C23,"") | G8: =IF(B8="POSTUPUJE",SUM(C8:F8),"vyřazen") | H8: =IF(ISNUMBER(G8),RANK(G8,$G$6:$G$8),"–")
A10: Citlivost: rozdíl 1. a 2. místa v bodech | G10: =LARGE($G$6:$G$8,1)-LARGE($G$6:$G$8,2)
A11: Pravidlo shody bodů: při rozdílu < 1,0 bodu rozhoduje vyšší skóre Arch & Sec; poté nižší TCO.

Sheet Hodnotici_arch
A1: Hodnoticí arch – výběrové řízení SENTINEL (k podpisu)
A2: Horizont Privátní banka, a.s. · Projekt SENTINEL – výměna KYC/AML řešení
A3: FIKTIVNÍ CVIČNÝ DOKUMENT – banka, osoby a dodavatelé jsou smyšlení.
A5: Předmět: | B5: Dodávka, implementace a podpora KYC/AML řešení (screening, KYC, monitoring transakcí, správa případů)
A6: Datum hodnocení: | B6: 2027-02-17
A7: Počet nabídek: | B7: 3
A9: Výsledek
A10: Dodavatel | B10: K.O. brána | C10: Celkem bodů | D10: Pořadí
A11: Dodavatel A | B11: =Vysledek!B6 | C11: =Vysledek!G6 | D11: =Vysledek!H6
A12: Dodavatel B | B12: =Vysledek!B7 | C12: =Vysledek!G7 | D12: =Vysledek!H7
A13: Dodavatel C | B13: =Vysledek!B8 | C13: =Vysledek!G8 | D13: =Vysledek!H8
A15: Doporučení komise: | B15: =IFERROR("Doporučujeme zahájit jednání o smlouvě s: "&INDEX(Vysledek!A6:A8,MATCH(1,Vysledek!H6:H8,0)),"")
A17: Zdůvodnění horších známek (výtah z listů 2–4)
A18: Dodavatel A – D1 | B18: Dvě reference z bank v EU, ale žádná z ČR – chybí přímá zkušenost s požadavky ČNB a FAÚ.
A19: Dodavatel A – D2 | B19: Vedoucí migrace má méně než 3 roky praxe s migrací AML dat.
A20: Dodavatel A – D3 | B20: Navrhuje cap sankcí 15 % ročního poplatku, Banka požaduje min. 30 %.
A21: Dodavatel B – D1 | B21: Reference pouze z retailových bank, žádná z privátního bankovnictví.
A22: Dodavatel B – D2 | B22: Navržený solution architekt nemá zkušenost s integrací přes Kafka.
A23: Dodavatel B – D4 | B23: Plán počítá s paralelním provozem jen 2 týdny místo požadovaných 4.
A24: Dodavatel B – FS 3 | B24: Sizing HW uveden jen pro PROD, chybí PreProd a DR.
A25: Dodavatel B – FS 4 | B25: Správa šifrovacích klíčů u dodavatele, ne v HSM Banky; chybí harmonogram penetračních testů.
A26: Dodavatel B – FS 5 | B26: Dodavatel navrhuje point-to-point integraci na core banking namísto požadované bankovní Kafka sběrnice.
A27: Dodavatel B – FS 6.6 | B27: Custom vývoj popsán obecně bez odhadu pracnosti a dopadu na upgrady.
A28: Dodavatel B – FS 7 | B28: Paralelní provoz jen 2 týdny a bez popsané rekonciliace historie případů.
A29: Dodavatel B – FS 9–10 | B29: Exit plán neřeší export auditních stop a historie screeningu.
... A38: Dodavatel C – FS 9–10 | B38: Zálohy mimo EU/EHP a nejasné subdodavatelské řetězení podpory; exit bez exportu konfigurace.
A40: Prohlášení: Členové komise prohlašují, že nejsou ve střetu zájmů ve vztahu k žádnému z uchazečů, hodnotili nezávisle podle předem schválené metodiky a výsledky odpovídají podkladům v tomto souboru.
A42: Jméno | B42: Role | C42: Postavení v komisi | D42: Datum | E42: Podpis
A43: Ing. Jana Novotná | B43: Business analytička / Product Owner AML | C43: předsedkyně, hlasuje
A44: Ing. Martin Dvořák | B44: Enterprise architekt (IT) | C44: hlasuje
A45: Mgr. Tomáš Svoboda | B45: Bezpečnostní architekt (útvar CISO) | C45: hlasuje
A46: JUDr. Lucie Malá | B46: Ředitelka Compliance, pověřená osoba (MLRO) | C46: hlasuje
A47: Ing. Pavel Černý | B47: Procurement | C47: bez hlasovacího práva, dohled nad procesem
A49: Schválil (sponzor projektu): | B49: Ing. Karel Procházka, člen představenstva | D49: Podpis:
